Workbook

Sheet Resumen Comparativo
B2: Comité de Nuevos Productos — Cobranza Cupón con TPV | Banco PagaTodo vs Efevoo Pay
B3: Modelo económico Sofo Plus a 5 años (60 meses) — cifras en MXN
B4: ="Tipo de cambio "&TEXT(Supuestos!$C$7,"0.00")&" MXN/USD · Propuestas: PagaTodo 17-sep-2026 y Efevoo 25-sep-2026 (vigencia 30 días)" -> Tipo de cambio 17.00 MXN/USD · Propuestas: PagaTodo 17-sep-2026 y Efevoo 25-sep-2026 (vigencia 30 días)
B6: Veredicto (VPN de la utilidad a 5 años) | C6: =IF(D33>C33,"Conviene EFEVOO PAY: "&TEXT(D33-C33,"$#,##0")&" MXN más de VPN a 5 años","Conviene BANCO PAGATODO: "&TEXT(C33-D33,"$#,##0")&" MXN más de VPN a 5 años") -> Conviene EFEVOO PAY: $43,059,035 MXN más de VPN a 5 años
B8: 1. Términos económicos de cada propuesta | C8: PagaTodo | D8: Efevoo
B9: Setup / implementación (USD) | C9: =Supuestos!$C$40 -> 15000 | D9: =Supuestos!$C$46 -> 20000
B10: Cuota fija mensual (USD) | C10: 0 | D10: =Supuestos!$C$50 -> 3950
B11: Mínimo mensual en régimen (USD) | C11: =Supuestos!$C$39 -> 5000 | D11: =Supuestos!$C$52 -> 0
B12: Renta TPV mensual mes 7+ (USD) / compra TPV (USD por unidad) | C12: =Supuestos!$C$31 -> 15 | D12: =Supuestos!$C$55 -> 131
B13: Servicing fee sobre cobranza | C13: =Supuestos!$C$34 -> 0.0075 | D13: 0
B14: % del margen neto MDR que se queda el proveedor | C14: =Supuestos!$C$33 -> 0.5 | D14: =IF(Supuestos!$C$20=0,0,1-Supuestos!$C$57/Supuestos!$C$20) -> 0
B15: Costo por transacción (USD) | C15: 0 | D15: =Supuestos!$C$51 -> 0.03
B16: Registro anual ante marcas (USD/año, desde el año 2) | C16: 0 | D16: =Supuestos!$C$53 -> 10000
B18: 2. Resultados anuales (MXN)
B19: Concepto | C19: 1 | D19: 2 | E19: 3 | F19: 4 | G19: 5 | H19: Total 5 años
B20: Banco PagaTodo
B21: Ingresos Sofo Plus | C21: =SUMIF('BP PagaTodo'!$C$6:$BJ$6,C$19,'BP PagaTodo'!$C$15:$BJ$15) -> 23266641 | D21: =SUMIF('BP PagaTodo'!$C$6:$BJ$6,D$19,'BP PagaTodo'!$C$15:$BJ$15) -> 85912975 | E21: =SUMIF('BP PagaTodo'!$C$6:$BJ$6,E$19,'BP PagaTodo'!$C$15:$BJ$15) -> 1.5228892e+08 | F21: =SUMIF('BP PagaTodo'!$C$6:$BJ$6,F$19,'BP PagaTodo'!$C$15:$BJ$15) -> 2.1843128e+08 | G21: =SUMIF('BP PagaTodo'!$C$6:$BJ$6,G$19,'BP PagaTodo'!$C$15:$BJ$15) -> 2.6496016e+08 | H21: =SUM(C21:G21) -> 7.4485999e+08
B22: Costo de fondeo | C22: =SUMIF('BP PagaTodo'!$C$6:$BJ$6,C$19,'BP PagaTodo'!$C$18:$BJ$18) -> 5910586.9 | D22: =SUMIF('BP PagaTodo'!$C$6:$BJ$6,D$19,'BP PagaTodo'!$C$18:$BJ$18) -> 22961728 | E22: =SUMIF('BP PagaTodo'!$C$6:$BJ$6,E$19,'BP PagaTodo'!$C$18:$BJ$18) -> 41051073 | F22: =SUMIF('BP PagaTodo'!$C$6:$BJ$6,F$19,'BP PagaTodo'!$C$18:$BJ$18) -> 59064767 | G22: =SUMIF('BP PagaTodo'!$C$6:$BJ$6,G$19,'BP PagaTodo'!$C$18:$BJ$18) -> 72147668 | H22: =SUM(C22:G22) -> 2.0113582e+08
B23: Pagos a PagaTodo (servicing + renta + top-up + setup) | C23: =SUMIF('BP PagaTodo'!$C$6:$BJ$6,C$19,'BP PagaTodo'!$C$23:$BJ$23)-C22 -> 931045.35 | D23: =SUMIF('BP PagaTodo'!$C$6:$BJ$6,D$19,'BP PagaTodo'!$C$23:$BJ$23)-D22 -> 3259633.4 | E23: =SUMIF('BP PagaTodo'!$C$6:$BJ$6,E$19,'BP PagaTodo'!$C$23:$BJ$23)-E22 -> 6172588.8 | F23: =SUMIF('BP PagaTodo'!$C$6:$BJ$6,F$19,'BP PagaTodo'!$C$23:$BJ$23)-F22 -> 9077758.8 | G23: =SUMIF('BP PagaTodo'!$C$6:$BJ$6,G$19,'BP PagaTodo'!$C$23:$BJ$23)-G22 -> 11426911 | H23: =SUM(C23:G23) -> 30867937
B24: Utilidad Sofo Plus | C24: =SUMIF('BP PagaTodo'!$C$6:$BJ$6,C$19,'BP PagaTodo'!$C$25:$BJ$25) -> 16425009 | D24: =SUMIF('BP PagaTodo'!$C$6:$BJ$6,D$19,'BP PagaTodo'!$C$25:$BJ$25) -> 59691614 | E24: =SUMIF('BP PagaTodo'!$C$6:$BJ$6,E$19,'BP PagaTodo'!$C$25:$BJ$25) -> 1.0506526e+08 | F24: =SUMIF('BP PagaTodo'!$C$6:$BJ$6,F$19,'BP PagaTodo'!$C$25:$BJ$25) -> 1.5028876e+08 | G24: =SUMIF('BP PagaTodo'!$C$6:$BJ$6,G$19,'BP PagaTodo'!$C$25:$BJ$25) -> 1.8138558e+08 | H24: =SUM(C24:G24) -> 5.1285623e+08
B25: Efevoo Pay
B26: Ingresos Sofo Plus | C26: =SUMIF('BP Efevoo'!$C$6:$BJ$6,C$19,'BP Efevoo'!$C$15:$BJ$15) -> 24829641 | D26: =SUMIF('BP Efevoo'!$C$6:$BJ$6,D$19,'BP Efevoo'!$C$15:$BJ$15) -> 93340975 | E26: =SUMIF('BP Efevoo'!$C$6:$BJ$6,E$19,'BP Efevoo'!$C$15:$BJ$15) -> 1.6630792e+08 | F26: =SUMIF('BP Efevoo'!$C$6:$BJ$6,F$19,'BP Efevoo'!$C$15:$BJ$15) -> 2.3902328e+08 | G26: =SUMIF('BP Efevoo'!$C$6:$BJ$6,G$19,'BP Efevoo'!$C$15:$BJ$15) -> 2.9083816e+08 | H26: =SUM(C26:G26) -> 8.1433999e+08
B27: Costo de fondeo | C27: =SUMIF('BP Efevoo'!$C$6:$BJ$6,C$19,'BP Efevoo'!$C$18:$BJ$18) -> 5910586.9 | D27: =SUMIF('BP Efevoo'!$C$6:$BJ$6,D$19,'BP Efevoo'!$C$18:$BJ$18) -> 22961728 | E27: =SUMIF('BP Efevoo'!$C$6:$BJ$6,E$19,'BP Efevoo'!$C$18:$BJ$18) -> 41051073 | F27: =SUMIF('BP Efevoo'!$C$6:$BJ$6,F$19,'BP Efevoo'!$C$18:$BJ$18) -> 59064767 | G27: =SUMIF('BP Efevoo'!$C$6:$BJ$6,G$19,'BP Efevoo'!$C$18:$BJ$18) -> 72147668 | H27: =SUM(C27:G27) -> 2.0113582e+08
B28: Pagos a Efevoo + operación propia | C28: =SUMIF('BP Efevoo'!$C$6:$BJ$6,C$19,'BP Efevoo'!$C$25:$BJ$25)-C27 -> 1917736 | D28: =SUMIF('BP Efevoo'!$C$6:$BJ$6,D$19,'BP Efevoo'!$C$25:$BJ$25)-D27 -> 3906634 | E28: =SUMIF('BP Efevoo'!$C$6:$BJ$6,E$19,'BP Efevoo'!$C$25:$BJ$25)-E27 -> 6149801 | F28: =SUMIF('BP Efevoo'!$C$6:$BJ$6,F$19,'BP Efevoo'!$C$25:$BJ$25)-F27 -> 8384621 | G28: =SUMIF('BP Efevoo'!$C$6:$BJ$6,G$19,'BP Efevoo'!$C$25:$BJ$25)-G27 -> 9970296 | H28: =SUM(C28:G28) -> 30329088
B29: Utilidad Sofo Plus | C29: =SUMIF('BP Efevoo'!$C$6:$BJ$6,C$19,'BP Efevoo'!$C$27:$BJ$27) -> 17001318 | D29: =SUMIF('BP Efevoo'!$C$6:$BJ$6,D$19,'BP Efevoo'!$C$27:$BJ$27) -> 66472613 | E29: =SUMIF('BP Efevoo'!$C$6:$BJ$6,E$19,'BP Efevoo'!$C$27:$BJ$27) -> 1.1910705e+08 | F29: =SUMIF('BP Efevoo'!$C$6:$BJ$6,F$19,'BP Efevoo'!$C$27:$BJ$27) -> 1.715739e+08 | G29: =SUMIF('BP Efevoo'!$C$6:$BJ$6,G$19,'BP Efevoo'!$C$27:$BJ$27) -> 2.087202e+08 | H29: =SUM(C29:G29) -> 5.8287508e+08
B30: Diferencia de utilidad (Efevoo − PagaTodo) | C30: =C29-C24 -> 576309.35 | D30: =D29-D24 -> 6780999.4 | E30: =E29-E24 -> 14041788 | F30: =F29-F24 -> 21285138 | G30: =G29-G24 -> 27334615 | H30: =H29-H24 -> 70018849
B32: 3. Indicadores clave a 5 años | C32: PagaTodo | D32: Efevoo
B33: VPN de la utilidad mensual (MXN) | C33: =NPV(((1+Supuestos!$C$8)^(1/12)-1),'BP PagaTodo'!C25:BJ25) -> 3.2343667e+08 | D33: =NPV(((1+Supuestos!$C$8)^(1/12)-1),'BP Efevoo'!C27:BJ27) -> 3.664957e+08
B34: Utilidad acumulada 60 meses (MXN) | C34: ='BP PagaTodo'!BJ26 -> 5.1285623e+08 | D34: ='BP Efevoo'!BJ28 -> 5.8287508e+08
B35: Pagos totales al proveedor en 60 meses (MXN) | C35: =SUM('BP PagaTodo'!C31:BJ31) -> 1.0034794e+08 | D35: =SUM('BP Efevoo'!C31:BJ31) -> 30329088
B36: Mes en que la utilidad acumulada es positiva | C36: =IF(MIN('BP PagaTodo'!C32:BJ32)=999,"no se alcanza",MIN('BP PagaTodo'!C32:BJ32)) -> 1 | D36: =IF(MIN('BP Efevoo'!C32:BJ32)=999,"no se alcanza",MIN('BP Efevoo'!C32:BJ32)) -> 3
B37: Utilidad más negativa de un mes (MXN) | C37: =MIN('BP PagaTodo'!C25:BJ25) -> 19483.204 | D37: =MIN('BP Efevoo'!C27:BJ27) -> -258094
B38: Meses con utilidad negativa | C38: =COUNTIF('BP PagaTodo'!C25:BJ25,"<0") -> 0 | D38: =COUNTIF('BP Efevoo'!C27:BJ27,"<0") -> 1
B39: Margen sobre ingresos (5 años) | C39: =IF(H21=0,0,H24/H21) -> 0.68852702 | D39: =IF(H26=0,0,H29/H26) -> 0.71576379
B40: Créditos vigentes para break-even mensual (en régimen) | C40: ='Economía por Crédito'!C22 -> 4 | D40: ='Economía por Crédito'!D22 -> 4
B41: Utilidad mensual en el mes 60 (MXN) | C41: ='BP PagaTodo'!BJ25 -> 15361571 | D41: ='BP Efevoo'!BJ27 -> 17754009
B42: Créditos vigentes a partir de los cuales conviene Efevoo (en régimen) | C42: ='Economía por Crédito'!C24 -> 25
B43: Holgura mensual promedio para la operación propia de agregador (MXN/mes) | C43: =H30/60 -> 1166980.8 | D43: Si operar como agregador (personal, cumplimiento, contracargos, soporte) cuesta más que esto al mes, conviene PagaTodo.
B44: Margen neto MDR mínimo con Efevoo para empatar con PagaTodo | C44: =Supuestos!$C$57-IF(SUM('Cartera 60M'!C76:BJ76)=0,0,H30/SUM('Cartera 60M'!C76:BJ76)) -> 0.0029767336 | D44: Si la "Tasa agregador" de Efevoo deja a Sofo Plus un margen neto menor a este %, conviene PagaTodo.
B45: 4. Supuestos del caso base (editar en la hoja Supuestos)
...

Sheet Supuestos
B2: Supuestos | Sofo Plus — Cobranza Cupón con TPV: Banco PagaTodo vs Efevoo Pay (5 años)
B3: Celdas en azul = datos editables · fondo amarillo = supuesto clave por validar · verde = liga a otra hoja · negro = fórmula
B6: 1. Generales | C6: Valor | D6: MXN | E6: Fuente / nota
B7: Tipo de cambio (MXN / USD) | C7: 17 | E7: Del modelo original PNB_Modelo_YG (FastPlus).
B8: Tasa de descuento anual para VPN | C8: 0.15 | E8: Supuesto editable; no viene de las propuestas. Se usa solo para comparar el valor presente.
B10: 2. Crédito SOFOM → Comercio (igual en ambos escenarios) | C10: Valor | D10: MXN | E10: Fuente / nota
B11: Facturación mensual con tarjeta por TPV (MXN) | C11: 1000000 | E11: Del modelo original.
B12: Ratio crédito / facturación mensual (x) | C12: 1.5 | E12: Del modelo original.
B13: Monto de crédito promedio (MXN) | C13: =Supuestos!$C$11*Supuestos!$C$12 -> 1500000
B14: Tasa anual del crédito | C14: 0.33 | E14: Del modelo original.
B15: Plazo (meses) — máximo 36 | C15: 12 | E15: Del modelo original.
B16: Costo de fondeo anual | C16: 0.1158 | E16: Del modelo original.
B17: Comisión de apertura de línea | C17: 0.03 | E17: Del modelo original.
B18: TPVs por comercio | C18: 1 | E18: Del modelo original.
B19: Ticket promedio por transacción con tarjeta (MXN) | C19: 500 | E19: NUEVO: necesario para calcular el costo por transacción de Efevoo (USD 0.03). Ajustar con el dato real de los comercios.
B20: Margen neto MDR total (% de facturación) — neto de intercambio, assessments y E-Global/Prosa | C20: 0.006 | E20: Del modelo original. Con PagaTodo se reparte; ver split abajo.
B22: 3. Plan de colocación (igual en ambos escenarios) | C22: Valor | D22: MXN | E22: Fuente / nota
B23: Créditos nuevos colocados en el mes 1 | C23: 2 | E23: Del modelo original.
B24: Objetivo de cartera (MXN) | C24: 500000000 | E24: Del modelo original.
B25: Mes objetivo para alcanzar la cartera | C25: 48 | E25: Del modelo original. Después de este mes la colocación mensual se mantiene constante hasta el mes 60.
B26: Modo de rampa ("Resolver para la meta" o "Rampa manual") | C26: Resolver para la meta | E26: "Resolver para la meta" calcula el incremento mensual para llegar al objetivo en el mes objetivo.
B27: Incremento mensual manual (créditos adicionales por mes) | C27: 1.5 | E27: Solo aplica en "Rampa manual".
B29: 4. Banco PagaTodo / Ya Ganaste — Propuesta 17-sep-2026 (USD) | C29: Valor | D29: MXN | E29: Fuente / nota
B30: Renta TPV mensual — meses 1 a 6 de cada TPV (USD) | C30: 10 | D30: =C30*Supuestos!$C$7 -> 170 | E30: Propuesta PagaTodo, numeral 1.
B31: Renta TPV mensual — mes 7 en adelante (USD) | C31: 15 | D31: =C31*Supuestos!$C$7 -> 255 | E31: Propuesta PagaTodo, numeral 1.
B32: Mes de antigüedad en que sube la renta | C32: 7 | E32: Igual que el modelo original: el escalón se aplica por antigüedad de cada TPV.
B33: Split del margen neto MDR para PagaTodo | C33: 0.5 | E33: Propuesta PagaTodo, numeral 2 (50% / 50%).
B34: Servicing fee (% de la cobranza del crédito vía TPV) | C34: 0.0075 | E34: Propuesta PagaTodo, numeral 3. Igual que el modelo original: se aplica sobre la cuota del crédito cobrada.
B35: Mínimo mensual — tramo 1 (USD) | C35: 0 | D35: =C35*Supuestos!$C$7 -> 0 | E35: Propuesta PagaTodo, numeral 4.
B36: Último mes del tramo 1 | C36: 2 | E36: La propuesta dice "Mes 1 y 2 / Mes 2 y 3 / Mes 5 en adelante" (error de redacción). Se usa 1-2, 3-4, 5+ como en el modelo original.
B37: Mínimo mensual — tramo 2 (USD) | C37: 2500 | D37: =C37*Supuestos!$C$7 -> 42500 | E37: Propuesta PagaTodo, numeral 4.
B38: Último mes del tramo 2 | C38: 4 | E38: Ver nota anterior.
B39: Mínimo mensual — resto del plazo (USD) | C39: 5000 | D39: =C39*Supuestos!$C$7 -> 85000 | E39: Propuesta PagaTodo, numeral 4.
B40: Setup total (USD) | C40: 15000 | D40: =C40*Supuestos!$C$7 -> 255000 | E40: Propuesta PagaTodo, numeral 5.
B41: % del setup pagado en el go live | C41: 0.5 | E41: Propuesta PagaTodo, numeral 5.
B42: Mes límite del segundo pago de setup | C42: 6 | E42: Propuesta PagaTodo: lo primero entre 20 TPV activas o el mes 6.
B43: Umbral de TPV activas para el segundo pago | C43: 20 | E43: Propuesta PagaTodo, numeral 5.
B45: 5. Efevoo Pay — Agregador marca blanca, propuesta 25-sep-2026 (USD) | C45: Valor | D45: MXN | E45: Fuente / nota
B46: Implementación inicial (USD, pago único) | C46: 20000 | D46: =C46*Supuestos!$C$7 -> 340000 | E46: Efevoo pág. 29. Incluye el registro ante Visa/MC del primer año.
B47: Renta dashboard de control interno y clientes (USD/mes) | C47: 3000 | D47: =C47*Supuestos!$C$7 -> 51000 | E47: Efevoo pág. 30.
...

Sheet Flujo Comercio-SOFOM
B2: Flujo Comercio ↔ SOFOM | Tabla de amortización de un crédito
B4: Monto crédito (MXN) | C4: =Supuestos!$C$13 -> 1500000
B5: Tasa anual | C5: =Supuestos!$C$14 -> 0.33
B6: Tasa mensual | C6: =C5/12 -> 0.0275
B7: Plazo (meses) | C7: =Supuestos!$C$15 -> 12
B8: Pago mensual (MXN) | C8: =C4*C6/(1-(1+C6)^(-C7)) -> 148453.06
B9: Comisión apertura (MXN) | C9: =C4*Supuestos!$C$17 -> 45000
B10: Costo fondeo mensual sobre monto (MXN) | C10: =C4*Supuestos!$C$16/12 -> 14475
B12: Periodo | C12: Balance inicial | D12: Pago mensual | E12: Interés | F12: Amortización | G12: Balance final
B13: 0 | C13: =C4 -> 1500000 | D13: 0 | E13: 0 | F13: 0 | G13: =C13 -> 1500000
B14: =B13+1 -> 1 | C14: =IF(B14>$C$7,0,G13) -> 1500000 | D14: =IF(C14<=0.005,0,$C$8) -> 148453.06 | E14: =C14*$C$6 -> 41250 | F14: =D14-E14 -> 107203.06 | G14: =C14-F14 -> 1392796.9
B15: =B14+1 -> 2 | C15: =IF(B15>$C$7,0,G14) -> 1392796.9 | D15: =IF(C15<=0.005,0,$C$8) -> 148453.06 | E15: =C15*$C$6 -> 38301.916 | F15: =D15-E15 -> 110151.15 | G15: =C15-F15 -> 1282645.8
B16: =B15+1 -> 3 | C16: =IF(B16>$C$7,0,G15) -> 1282645.8 | D16: =IF(C16<=0.005,0,$C$8) -> 148453.06 | E16: =C16*$C$6 -> 35272.759 | F16: =D16-E16 -> 113180.31 | G16: =C16-F16 -> 1169465.5
B17: =B16+1 -> 4 | C17: =IF(B17>$C$7,0,G16) -> 1169465.5 | D17: =IF(C17<=0.005,0,$C$8) -> 148453.06 | E17: =C17*$C$6 -> 32160.301 | F17: =D17-E17 -> 116292.76 | G17: =C17-F17 -> 1053172.7
B18: =B17+1 -> 5 | C18: =IF(B18>$C$7,0,G17) -> 1053172.7 | D18: =IF(C18<=0.005,0,$C$8) -> 148453.06 | E18: =C18*$C$6 -> 28962.25 | F18: =D18-E18 -> 119490.82 | G18: =C18-F18 -> 933681.9
B19: =B18+1 -> 6 | C19: =IF(B19>$C$7,0,G18) -> 933681.9 | D19: =IF(C19<=0.005,0,$C$8) -> 148453.06 | E19: =C19*$C$6 -> 25676.252 | F19: =D19-E19 -> 122776.81 | G19: =C19-F19 -> 810905.09
B20: =B19+1 -> 7 | C20: =IF(B20>$C$7,0,G19) -> 810905.09 | D20: =IF(C20<=0.005,0,$C$8) -> 148453.06 | E20: =C20*$C$6 -> 22299.89 | F20: =D20-E20 -> 126153.17 | G20: =C20-F20 -> 684751.91
B21: =B20+1 -> 8 | C21: =IF(B21>$C$7,0,G20) -> 684751.91 | D21: =IF(C21<=0.005,0,$C$8) -> 148453.06 | E21: =C21*$C$6 -> 18830.678 | F21: =D21-E21 -> 129622.39 | G21: =C21-F21 -> 555129.53
B22: =B21+1 -> 9 | C22: =IF(B22>$C$7,0,G21) -> 555129.53 | D22: =IF(C22<=0.005,0,$C$8) -> 148453.06 | E22: =C22*$C$6 -> 15266.062 | F22: =D22-E22 -> 133187 | G22: =C22-F22 -> 421942.52
B23: =B22+1 -> 10 | C23: =IF(B23>$C$7,0,G22) -> 421942.52 | D23: =IF(C23<=0.005,0,$C$8) -> 148453.06 | E23: =C23*$C$6 -> 11603.419 | F23: =D23-E23 -> 136849.65 | G23: =C23-F23 -> 285092.88
B24: =B23+1 -> 11 | C24: =IF(B24>$C$7,0,G23) -> 285092.88 | D24: =IF(C24<=0.005,0,$C$8) -> 148453.06 | E24: =C24*$C$6 -> 7840.0542 | F24: =D24-E24 -> 140613.01 | G24: =C24-F24 -> 144479.87
B25: =B24+1 -> 12 | C25: =IF(B25>$C$7,0,G24) -> 144479.87 | D25: =IF(C25<=0.005,0,$C$8) -> 148453.06 | E25: =C25*$C$6 -> 3973.1964 | F25: =D25-E25 -> 144479.87 | G25: =C25-F25 -> 4.3655746e-09
... B49: =B48+1 -> 36 | C49: =IF(B49>$C$7,0,G48) -> 0 | D49: =IF(C49<=0.005,0,$C$8) -> 0 | E49: =C49*$C$6 -> 0 | F49: =D49-E49 -> 0 | G49: =C49-F49 -> 0
B52: P&L de la SOFOM por crédito
B53: Total intereses cobrados (MXN) | C53: =SUM(E14:E49) -> 281436.78
B54: Comisión apertura (MXN) | C54: =C9 -> 45000
B55: Ingreso total (MXN) | C55: =C53+C54 -> 326436.78
B56: Costo de fondeo total (MXN, sobre saldo) | C56: =SUM(C14:C49)*Supuestos!$C$16/12 -> 98758.724
B57: Utilidad SOFOM por crédito antes de proveedor (MXN) | C57: =C55-C56 -> 227678.05

Sheet Cartera 60M
B2: Cartera y volumen | Plan de colocación a 60 meses (común para ambos proveedores)
B3: Cifras en MXN. La cartera, la cobranza y las TPV activas son idénticas en los dos escenarios; solo cambian los costos del proveedor.
B5: Monto de crédito promedio (MXN) | C5: =Supuestos!$C$13 -> 1500000
B6: Tasa mensual | C6: =Supuestos!$C$14/12 -> 0.0275
B7: Plazo (meses) | C7: =Supuestos!$C$15 -> 12
B8: Pago mensual por crédito (MXN) | C8: =C5*C6/(1-(1+C6)^(-C7)) -> 148453.06
B9: Créditos nuevos mes 1 | C9: =Supuestos!$C$23 -> 2
B10: Objetivo de cartera (MXN) | C10: =Supuestos!$C$24 -> 500000000
B11: Mes objetivo | C11: =Supuestos!$C$25 -> 48
B12: Suma de factores de saldo insoluto (Sf) | C12: =SUM(C24:C59) -> 5.8227097
B13: Suma ponderada para la rampa (Sw) | C13: =SUMPRODUCT(D24:D59,C24:C59) -> 253.70006
B14: Incremento mensual requerido para la meta (créditos/mes) | C14: =IF(C13=0,0,(C10/C5-C9*C12)/C13) -> 1.2679851
B15: Modo de rampa | C15: =Supuestos!$C$26 -> Resolver para la meta
B16: Incremento mensual manual | C16: =Supuestos!$C$27 -> 1.5
B17: Incremento mensual aplicado | C17: =IF(C15="Rampa manual",C16,C14) -> 1.2679851
B18: Mes del 2º pago de setup PagaTodo (20 TPV o mes 6, lo primero) | C18: =MIN(Supuestos!$C$42,MIN(C80:BJ80)) -> 5
B19: Cartera alcanzada en el mes objetivo (MXN) | C19: =INDEX(C75:BJ75,1,C11) -> 5.0046598e+08
B20: % del objetivo alcanzado | C20: =IF(C10=0,0,C19/C10) -> 1.000932
B23: Pagos realizados | C23: Factor saldo insoluto | D23: Peso para la rampa
B24: 1 | C24: =IF(B24>$C$7,0,(1-(1+$C$6)^(-($C$7-B24)))/(1-(1+$C$6)^(-$C$7))) -> 0.92853129 | D24: =IF(B24>$C$7,0,$C$11-B24) -> 47
B25: 2 | C25: =IF(B25>$C$7,0,(1-(1+$C$6)^(-($C$7-B25)))/(1-(1+$C$6)^(-$C$7))) -> 0.85509719 | D25: =IF(B25>$C$7,0,$C$11-B25) -> 46
B26: 3 | C26: =IF(B26>$C$7,0,(1-(1+$C$6)^(-($C$7-B26)))/(1-(1+$C$6)^(-$C$7))) -> 0.77964365 | D26: =IF(B26>$C$7,0,$C$11-B26) -> 45
B27: 4 | C27: =IF(B27>$C$7,0,(1-(1+$C$6)^(-($C$7-B27)))/(1-(1+$C$6)^(-$C$7))) -> 0.70211514 | D27: =IF(B27>$C$7,0,$C$11-B27) -> 44
B28: 5 | C28: =IF(B28>$C$7,0,(1-(1+$C$6)^(-($C$7-B28)))/(1-(1+$C$6)^(-$C$7))) -> 0.6224546 | D28: =IF(B28>$C$7,0,$C$11-B28) -> 43
B29: 6 | C29: =IF(B29>$C$7,0,(1-(1+$C$6)^(-($C$7-B29)))/(1-(1+$C$6)^(-$C$7))) -> 0.54060339 | D29: =IF(B29>$C$7,0,$C$11-B29) -> 42
B30: 7 | C30: =IF(B30>$C$7,0,(1-(1+$C$6)^(-($C$7-B30)))/(1-(1+$C$6)^(-$C$7))) -> 0.45650128 | D30: =IF(B30>$C$7,0,$C$11-B30) -> 41
B31: 8 | C31: =IF(B31>$C$7,0,(1-(1+$C$6)^(-($C$7-B31)))/(1-(1+$C$6)^(-$C$7))) -> 0.37008635 | D31: =IF(B31>$C$7,0,$C$11-B31) -> 40
B32: 9 | C32: =IF(B32>$C$7,0,(1-(1+$C$6)^(-($C$7-B32)))/(1-(1+$C$6)^(-$C$7))) -> 0.28129502 | D32: =IF(B32>$C$7,0,$C$11-B32) -> 39
B33: 10 | C33: =IF(B33>$C$7,0,(1-(1+$C$6)^(-($C$7-B33)))/(1-(1+$C$6)^(-$C$7))) -> 0.19006192 | D33: =IF(B33>$C$7,0,$C$11-B33) -> 38
B34: 11 | C34: =IF(B34>$C$7,0,(1-(1+$C$6)^(-($C$7-B34)))/(1-(1+$C$6)^(-$C$7))) -> 0.096319912 | D34: =IF(B34>$C$7,0,$C$11-B34) -> 37
B35: 12 | C35: =IF(B35>$C$7,0,(1-(1+$C$6)^(-($C$7-B35)))/(1-(1+$C$6)^(-$C$7))) -> 0 | D35: =IF(B35>$C$7,0,$C$11-B35) -> 36
... B59: 36 | C59: =IF(B59>$C$7,0,(1-(1+$C$6)^(-($C$7-B59)))/(1-(1+$C$6)^(-$C$7))) -> 0 | D59: =IF(B59>$C$7,0,$C$11-B59) -> 0
B61: Proyección mensual 60 meses (MXN)
B62: Mes # | C62: 1 | D62: =C62+1 -> 2 | E62: =D62+1 -> 3 | F62: =E62+1 -> 4 | G62: =F62+1 -> 5 | H62: =G62+1 -> 6 | I62: =H62+1 -> 7 | J62: =I62+1 -> 8 | K62: =J62+1 -> 9 | ... BJ62: =BI62+1 -> 60
B63: Año | C63: =ROUNDUP(C62/12,0) -> 1 | D63: =ROUNDUP(D62/12,0) -> 1 | E63: =ROUNDUP(E62/12,0) -> 1 | F63: =ROUNDUP(F62/12,0) -> 1 | G63: =ROUNDUP(G62/12,0) -> 1 | H63: =ROUNDUP(H62/12,0) -> 1 | I63: =ROUNDUP(I62/12,0) -> 1 | J63: =ROUNDUP(J62/12,0) -> 1 | ... BJ63: =ROUNDUP(BJ62/12,0) -> 5
B64: Créditos nuevos colocados | C64: =ROUND(MAX(0,$C$9+(MIN(C62,$C$11)-1)*$C$17),0) -> 2 | D64: =ROUND(MAX(0,$C$9+(MIN(D62,$C$11)-1)*$C$17),0) -> 3 | E64: =ROUND(MAX(0,$C$9+(MIN(E62,$C$11)-1)*$C$17),0) -> 5 | F64: =ROUND(MAX(0,$C$9+(MIN(F62,$C$11)-1)*$C$17),0) -> 6 | G64: =ROUND(MAX(0,$C$9+(MIN(G62,$C$11)-1)*$C$17),0) -> 7 | H64: =ROUND(MAX(0,$C$9+(MIN(H62,$C$11)-1)*$C$17),0) -> 8 | I64: =ROUND(MAX(0,$C$9+(MIN(I62,$C$11)-1)*$C$17),0) -> 10 | J64: =ROUND(MAX(0,$C$9+(MIN(J62,$C$11)-1)*$C$17),0) -> 11 | ... BJ64: =ROUND(MAX(0,$C$9+(MIN(BJ62,$C$11)-1)*$C$17),0) -> 62
B65: Créditos acumulados originados | C65: =C64 -> 2 | D65: =C65+D64 -> 5 | E65: =D65+E64 -> 10 | F65: =E65+F64 -> 16 | G65: =F65+G64 -> 23 | H65: =G65+H64 -> 31 | I65: =H65+I64 -> 41 | J65: =I65+J64 -> 52 | K65: =J65+K64 -> 64 | ... BJ65: =BI65+BJ64 -> 2271
B66: Créditos vigentes | C66: =C65-IF(C62>$C$7,INDEX($C$65:$BJ$65,1,C62-$C$7),0) -> 2 | D66: =D65-IF(D62>$C$7,INDEX($C$65:$BJ$65,1,D62-$C$7),0) -> 5 | E66: =E65-IF(E62>$C$7,INDEX($C$65:$BJ$65,1,E62-$C$7),0) -> 10 | F66: =F65-IF(F62>$C$7,INDEX($C$65:$BJ$65,1,F62-$C$7),0) -> 16 | G66: =G65-IF(G62>$C$7,INDEX($C$65:$BJ$65,1,G62-$C$7),0) -> 23 | H66: =H65-IF(H62>$C$7,INDEX($C$65:$BJ$65,1,H62-$C$7),0) -> 31 | I66: =I65-IF(I62>$C$7,INDEX($C$65:$BJ$65,1,I62-$C$7),0) -> 41 | J66: =J65-IF(J62>$C$7,INDEX($C$65:$BJ$65,1,J62-$C$7),0) -> 52 | ... BJ66: =BJ65-IF(BJ62>$C$7,INDEX($C$65:$BJ$65,1,BJ62-$C$7),0) -> 744
B67: TPV activas | C67: =C66*Supuestos!$C$18 -> 2 | D67: =D66*Supuestos!$C$18 -> 5 | E67: =E66*Supuestos!$C$18 -> 10 | F67: =F66*Supuestos!$C$18 -> 16 | G67: =G66*Supuestos!$C$18 -> 23 | H67: =H66*Supuestos!$C$18 -> 31 | I67: =I66*Supuestos!$C$18 -> 41 | J67: =J66*Supuestos!$C$18 -> 52 | ... BJ67: =BJ66*Supuestos!$C$18 -> 744
B68: TPV con antigüedad ≥ escalón de renta (auxiliar PagaTodo) | C68: =MAX(0,IF(C62-Supuestos!$C$32+1>=1,INDEX($C$65:$BJ$65,1,C62-Supuestos!$C$32+1),0)-IF(C62>$C$7,INDEX($C$65:$BJ$65,1,C62-$C$7),0))*Supuestos!$C$18 -> 0 | D68: =MAX(0,IF(D62-Supuestos!$C$32+1>=1,INDEX($C$65:$BJ$65,1,D62-Supuestos!$C$32+1),0)-IF(D62>$C$7,INDEX($C$65:$BJ$65,1,D62-$C$7),0))*Supuestos!$C$18 -> 0 | E68: =MAX(0,IF(E62-Supuestos!$C$32+1>=1,INDEX($C$65:$BJ$65,1,E62-Supuestos!$C$32+1),0)-IF(E62>$C$7,INDEX($C$65:$BJ$65,1,E62-$C$7),0))*Supuestos!$C$18 -> 0 | F68: =MAX(0,IF(F62-Supuestos!$C$32+1>=1,INDEX($C$65:$BJ$65,1,F62-Supuestos!$C$32+1),0)-IF(F62>$C$7,INDEX($C$65:$BJ$65,1,F62-$C$7),0))*Supuestos!$C$18 -> 0 | G68: =MAX(0,IF(G62-Supuestos!$C$32+1>=1,INDEX($C$65:$BJ$65,1,G62-Supuestos!$C$32+1),0)-IF(G62>$C$7,INDEX($C$65:$BJ$65,1,G62-$C$7),0))*Supuestos!$C$18 -> 0 | H68: =MAX(0,IF(H62-Supuestos!$C$32+1>=1,INDEX($C$65:$BJ$65,1,H62-Supuestos!$C$32+1),0)-IF(H62>$C$7,INDEX($C$65:$BJ$65,1,H62-$C$7),0))*Supuestos!$C$18 -> 0 | I68: =MAX(0,IF(I62-Supuestos!$C$32+1>=1,INDEX($C$65:$BJ$65,1,I62-Supuestos!$C$32+1),0)-IF(I62>$C$7,INDEX($C$65:$BJ$65,1,I62-$C$7),0))*Supuestos!$C$18 -> 2 | J68: =MAX(0,IF(J62-Supuestos!$C$32+1>=1,INDEX($C$65:$BJ$65,1,J62-Supuestos!$C$32+1),0)-IF(J62>$C$7,INDEX($C$65:$BJ$65,1,J62-$C$7),0))*Supuestos!$C$18 -> 5 | ... BJ68: =MAX(0,IF(BJ62-Supuestos!$C$32+1>=1,INDEX($C$65:$BJ$65,1,BJ62-Supuestos!$C$32+1),0)-IF(BJ62>$C$7,INDEX($C$65:$BJ$65,1,BJ62-$C$7),0))*Supuestos!$C$18 -> 372
...

Sheet BP PagaTodo
B2: Business Plan 60 meses | Sofo Plus con Banco PagaTodo (propuesta 17-sep-2026)
B3: Cifras en MXN. Flujo mensual de Sofo Plus: ingresos del crédito + su parte del MDR, menos fondeo y pagos a PagaTodo.
B5: Mes # | C5: ='Cartera 60M'!C62 -> 1 | D5: ='Cartera 60M'!D62 -> 2 | E5: ='Cartera 60M'!E62 -> 3 | F5: ='Cartera 60M'!F62 -> 4 | G5: ='Cartera 60M'!G62 -> 5 | H5: ='Cartera 60M'!H62 -> 6 | I5: ='Cartera 60M'!I62 -> 7 | J5: ='Cartera 60M'!J62 -> 8 | ... BJ5: ='Cartera 60M'!BJ62 -> 60
B6: Año | C6: ='Cartera 60M'!C63 -> 1 | D6: ='Cartera 60M'!D63 -> 1 | E6: ='Cartera 60M'!E63 -> 1 | F6: ='Cartera 60M'!F63 -> 1 | G6: ='Cartera 60M'!G63 -> 1 | H6: ='Cartera 60M'!H63 -> 1 | I6: ='Cartera 60M'!I63 -> 1 | J6: ='Cartera 60M'!J63 -> 1 | ... BJ6: ='Cartera 60M'!BJ63 -> 5
B7: Créditos vigentes | C7: ='Cartera 60M'!C66 -> 2 | D7: ='Cartera 60M'!D66 -> 5 | E7: ='Cartera 60M'!E66 -> 10 | F7: ='Cartera 60M'!F66 -> 16 | G7: ='Cartera 60M'!G66 -> 23 | H7: ='Cartera 60M'!H66 -> 31 | I7: ='Cartera 60M'!I66 -> 41 | J7: ='Cartera 60M'!J66 -> 52 | ... BJ7: ='Cartera 60M'!BJ66 -> 744
B8: TPV activas | C8: ='Cartera 60M'!C67 -> 2 | D8: ='Cartera 60M'!D67 -> 5 | E8: ='Cartera 60M'!E67 -> 10 | F8: ='Cartera 60M'!F67 -> 16 | G8: ='Cartera 60M'!G67 -> 23 | H8: ='Cartera 60M'!H67 -> 31 | I8: ='Cartera 60M'!I67 -> 41 | J8: ='Cartera 60M'!J67 -> 52 | ... BJ8: ='Cartera 60M'!BJ67 -> 744
B9: Cartera al cierre (MXN) | C9: ='Cartera 60M'!C75 -> 2785593.9 | D9: ='Cartera 60M'!D75 -> 6743682.4 | E9: ='Cartera 60M'!E75 -> 13150853 | F9: ='Cartera 60M'!F75 -> 20384752 | G9: ='Cartera 60M'!G75 -> 28319663 | H9: ='Cartera 60M'!H75 -> 36826408 | I9: ='Cartera 60M'!I75 -> 47165059 | J9: ='Cartera 60M'!J75 -> 57696289 | ... BJ9: ='Cartera 60M'!BJ75 -> 5.4151201e+08
B11: Ingresos Sofo Plus
B12: Comisión de apertura | C12: ='Cartera 60M'!C70*Supuestos!$C$17 -> 90000 | D12: ='Cartera 60M'!D70*Supuestos!$C$17 -> 135000 | E12: ='Cartera 60M'!E70*Supuestos!$C$17 -> 225000 | F12: ='Cartera 60M'!F70*Supuestos!$C$17 -> 270000 | G12: ='Cartera 60M'!G70*Supuestos!$C$17 -> 315000 | H12: ='Cartera 60M'!H70*Supuestos!$C$17 -> 360000 | I12: ='Cartera 60M'!I70*Supuestos!$C$17 -> 450000 | J12: ='Cartera 60M'!J70*Supuestos!$C$17 -> 495000 | ... BJ12: ='Cartera 60M'!BJ70*Supuestos!$C$17 -> 2790000
B13: Intereses | C13: ='Cartera 60M'!C72 -> 82500 | D13: ='Cartera 60M'!D72 -> 200353.83 | E13: ='Cartera 60M'!E72 -> 391701.27 | F13: ='Cartera 60M'!F72 -> 609148.46 | G13: ='Cartera 60M'!G72 -> 849330.69 | H13: ='Cartera 60M'!H72 -> 1108790.7 | I13: ='Cartera 60M'!I72 -> 1425226.2 | J13: ='Cartera 60M'!J72 -> 1750789.1 | ... BJ13: ='Cartera 60M'!BJ72 -> 17449080
B14: MDR — parte de Sofo Plus (1 − split PagaTodo) | C14: ='Cartera 60M'!C76*Supuestos!$C$20*(1-Supuestos!$C$33) -> 6000 | D14: ='Cartera 60M'!D76*Supuestos!$C$20*(1-Supuestos!$C$33) -> 15000 | E14: ='Cartera 60M'!E76*Supuestos!$C$20*(1-Supuestos!$C$33) -> 30000 | F14: ='Cartera 60M'!F76*Supuestos!$C$20*(1-Supuestos!$C$33) -> 48000 | G14: ='Cartera 60M'!G76*Supuestos!$C$20*(1-Supuestos!$C$33) -> 69000 | H14: ='Cartera 60M'!H76*Supuestos!$C$20*(1-Supuestos!$C$33) -> 93000 | I14: ='Cartera 60M'!I76*Supuestos!$C$20*(1-Supuestos!$C$33) -> 123000 | J14: ='Cartera 60M'!J76*Supuestos!$C$20*(1-Supuestos!$C$33) -> 156000 | ... BJ14: ='Cartera 60M'!BJ76*Supuestos!$C$20*(1-Supuestos!$C$33) -> 2232000
B15: Total ingresos | C15: =SUM(C12:C14) -> 178500 | D15: =SUM(D12:D14) -> 350353.83 | E15: =SUM(E12:E14) -> 646701.27 | F15: =SUM(F12:F14) -> 927148.46 | G15: =SUM(G12:G14) -> 1233330.7 | H15: =SUM(H12:H14) -> 1561790.7 | I15: =SUM(I12:I14) -> 1998226.2 | J15: =SUM(J12:J14) -> 2401789.1 | ... BJ15: =SUM(BJ12:BJ14) -> 22471080
B17: Costos Sofo Plus
B18: Costo de fondeo | C18: ='Cartera 60M'!C71*Supuestos!$C$16/12 -> 28950 | D18: ='Cartera 60M'!D71*Supuestos!$C$16/12 -> 70305.981 | E18: ='Cartera 60M'!E71*Supuestos!$C$16/12 -> 137451.53 | F18: ='Cartera 60M'!F71*Supuestos!$C$16/12 -> 213755.73 | G18: ='Cartera 60M'!G71*Supuestos!$C$16/12 -> 298037.86 | H18: ='Cartera 60M'!H71*Supuestos!$C$16/12 -> 389084.74 | I18: ='Cartera 60M'!I71*Supuestos!$C$16/12 -> 500124.84 | J18: ='Cartera 60M'!J71*Supuestos!$C$16/12 -> 614367.82 | ... BJ18: ='Cartera 60M'!BJ71*Supuestos!$C$16/12 -> 6123040.9
B19: Servicing fee a PagaTodo (0.75% de la cuota cobrada) | C19: ='Cartera 60M'!C73*Supuestos!$C$34 -> 2226.796 | D19: ='Cartera 60M'!D73*Supuestos!$C$34 -> 5566.9899 | E19: ='Cartera 60M'!E73*Supuestos!$C$34 -> 11133.98 | F19: ='Cartera 60M'!F73*Supuestos!$C$34 -> 17814.368 | G19: ='Cartera 60M'!G73*Supuestos!$C$34 -> 25608.154 | H19: ='Cartera 60M'!H73*Supuestos!$C$34 -> 34515.338 | I19: ='Cartera 60M'!I73*Supuestos!$C$34 -> 45649.317 | J19: ='Cartera 60M'!J73*Supuestos!$C$34 -> 57896.695 | ... BJ19: ='Cartera 60M'!BJ73*Supuestos!$C$34 -> 828368.1
B20: Renta TPV a PagaTodo | C20: ='Cartera 60M'!C68*Supuestos!$D$31+'Cartera 60M'!C69*Supuestos!$D$30 -> 340 | D20: ='Cartera 60M'!D68*Supuestos!$D$31+'Cartera 60M'!D69*Supuestos!$D$30 -> 850 | E20: ='Cartera 60M'!E68*Supuestos!$D$31+'Cartera 60M'!E69*Supuestos!$D$30 -> 1700 | F20: ='Cartera 60M'!F68*Supuestos!$D$31+'Cartera 60M'!F69*Supuestos!$D$30 -> 2720 | G20: ='Cartera 60M'!G68*Supuestos!$D$31+'Cartera 60M'!G69*Supuestos!$D$30 -> 3910 | H20: ='Cartera 60M'!H68*Supuestos!$D$31+'Cartera 60M'!H69*Supuestos!$D$30 -> 5270 | I20: ='Cartera 60M'!I68*Supuestos!$D$31+'Cartera 60M'!I69*Supuestos!$D$30 -> 7140 | J20: ='Cartera 60M'!J68*Supuestos!$D$31+'Cartera 60M'!J69*Supuestos!$D$30 -> 9265 | ... BJ20: ='Cartera 60M'!BJ68*Supuestos!$D$31+'Cartera 60M'!BJ69*Supuestos!$D$30 -> 158100
B21: Top-up al mínimo mensual | C21: =MAX(0,C30-C29) -> 0 | D21: =MAX(0,D30-D29) -> 0 | E21: =MAX(0,E30-E29) -> 0 | F21: =MAX(0,F30-F29) -> 0 | G21: =MAX(0,G30-G29) -> 0 | H21: =MAX(0,H30-H29) -> 0 | I21: =MAX(0,I30-I29) -> 0 | J21: =MAX(0,J30-J29) -> 0 | ... BJ21: =MAX(0,BJ30-BJ29) -> 0
B22: Setup | C22: =IF(C5=1,Supuestos!$D$40*Supuestos!$C$41,0)+IF(C5='Cartera 60M'!$C$18,Supuestos!$D$40*(1-Supuestos!$C$41),0) -> 127500 | D22: =IF(D5=1,Supuestos!$D$40*Supuestos!$C$41,0)+IF(D5='Cartera 60M'!$C$18,Supuestos!$D$40*(1-Supuestos!$C$41),0) -> 0 | E22: =IF(E5=1,Supuestos!$D$40*Supuestos!$C$41,0)+IF(E5='Cartera 60M'!$C$18,Supuestos!$D$40*(1-Supuestos!$C$41),0) -> 0 | F22: =IF(F5=1,Supuestos!$D$40*Supuestos!$C$41,0)+IF(F5='Cartera 60M'!$C$18,Supuestos!$D$40*(1-Supuestos!$C$41),0) -> 0 | G22: =IF(G5=1,Supuestos!$D$40*Supuestos!$C$41,0)+IF(G5='Cartera 60M'!$C$18,Supuestos!$D$40*(1-Supuestos!$C$41),0) -> 127500 | H22: =IF(H5=1,Supuestos!$D$40*Supuestos!$C$41,0)+IF(H5='Cartera 60M'!$C$18,Supuestos!$D$40*(1-Supuestos!$C$41),0) -> 0 | I22: =IF(I5=1,Supuestos!$D$40*Supuestos!$C$41,0)+IF(I5='Cartera 60M'!$C$18,Supuestos!$D$40*(1-Supuestos!$C$41),0) -> 0 | J22: =IF(J5=1,Supuestos!$D$40*Supuestos!$C$41,0)+IF(J5='Cartera 60M'!$C$18,Supuestos!$D$40*(1-Supuestos!$C$41),0) -> 0 | ... BJ22: =IF(BJ5=1,Supuestos!$D$40*Supuestos!$C$41,0)+IF(BJ5='Cartera 60M'!$C$18,Supuestos!$D$40*(1-Supuestos!$C$41),0) -> 0
B23: Total costos | C23: =SUM(C18:C22) -> 159016.8 | D23: =SUM(D18:D22) -> 76722.971 | E23: =SUM(E18:E22) -> 150285.51 | F23: =SUM(F18:F22) -> 234290.1 | G23: =SUM(G18:G22) -> 455056.01 | H23: =SUM(H18:H22) -> 428870.08 | I23: =SUM(I18:I22) -> 552914.16 | J23: =SUM(J18:J22) -> 681529.51 | ... BJ23: =SUM(BJ18:BJ22) -> 7109509
B25: Utilidad mensual Sofo Plus | C25: =C15-C23 -> 19483.204 | D25: =D15-D23 -> 273630.86 | E25: =E15-E23 -> 496415.75 | F25: =F15-F23 -> 692858.36 | G25: =G15-G23 -> 778274.68 | H25: =H15-H23 -> 1132920.6 | I25: =I15-I23 -> 1445312.1 | J25: =J15-J23 -> 1720259.6 | ... BJ25: =BJ15-BJ23 -> 15361571
B26: Utilidad acumulada | C26: =C25 -> 19483.204 | D26: =C26+D25 -> 293114.06 | E26: =D26+E25 -> 789529.82 | F26: =E26+F25 -> 1482388.2 | G26: =F26+G25 -> 2260662.9 | H26: =G26+H25 -> 3393583.5 | I26: =H26+I25 -> 4838895.6 | J26: =I26+J25 -> 6559155.2 | K26: =J26+K25 -> 8559346.4 | ... BJ26: =BI26+BJ25 -> 5.1285623e+08
B27: Margen sobre ingresos | C27: =IF(C15=0,0,C25/C15) -> 0.1091496 | D27: =IF(D15=0,0,D25/D15) -> 0.7810129 | E27: =IF(E15=0,0,E25/E15) -> 0.76761215 | F27: =IF(F15=0,0,F25/F15) -> 0.74730034 | G27: =IF(G15=0,0,G25/G15) -> 0.63103487 | H27: =IF(H15=0,0,H25/H15) -> 0.7253985 | I27: =IF(I15=0,0,I25/I15) -> 0.72329752 | J27: =IF(J15=0,0,J25/J15) -> 0.7162409 | ... BJ27: =IF(BJ15=0,0,BJ25/BJ15) -> 0.68361517
B28: Control del mínimo y pagos a PagaTodo
B29: Margen bruto generado para PagaTodo (su % MDR + servicing + renta) | C29: ='Cartera 60M'!C76*Supuestos!$C$20*Supuestos!$C$33+C19+C20 -> 8566.796 | D29: ='Cartera 60M'!D76*Supuestos!$C$20*Supuestos!$C$33+D19+D20 -> 21416.99 | E29: ='Cartera 60M'!E76*Supuestos!$C$20*Supuestos!$C$33+E19+E20 -> 42833.98 | F29: ='Cartera 60M'!F76*Supuestos!$C$20*Supuestos!$C$33+F19+F20 -> 68534.368 | G29: ='Cartera 60M'!G76*Supuestos!$C$20*Supuestos!$C$33+G19+G20 -> 98518.154 | H29: ='Cartera 60M'!H76*Supuestos!$C$20*Supuestos!$C$33+H19+H20 -> 132785.34 | I29: ='Cartera 60M'!I76*Supuestos!$C$20*Supuestos!$C$33+I19+I20 -> 175789.32 | J29: ='Cartera 60M'!J76*Supuestos!$C$20*Supuestos!$C$33+J19+J20 -> 223161.7 | ... BJ29: ='Cartera 60M'!BJ76*Supuestos!$C$20*Supuestos!$C$33+BJ19+BJ20 -> 3218468.1
B30: Mínimo mensual exigido por PagaTodo | C30: =IF(C5<=Supuestos!$C$36,Supuestos!$D$35,IF(C5<=Supuestos!$C$38,Supuestos!$D$37,Supuestos!$D$39)) -> 0 | D30: =IF(D5<=Supuestos!$C$36,Supuestos!$D$35,IF(D5<=Supuestos!$C$38,Supuestos!$D$37,Supuestos!$D$39)) -> 0 | E30: =IF(E5<=Supuestos!$C$36,Supuestos!$D$35,IF(E5<=Supuestos!$C$38,Supuestos!$D$37,Supuestos!$D$39)) -> 42500 | F30: =IF(F5<=Supuestos!$C$36,Supuestos!$D$35,IF(F5<=Supuestos!$C$38,Supuestos!$D$37,Supuestos!$D$39)) -> 42500 | G30: =IF(G5<=Supuestos!$C$36,Supuestos!$D$35,IF(G5<=Supuestos!$C$38,Supuestos!$D$37,Supuestos!$D$39)) -> 85000 | H30: =IF(H5<=Supuestos!$C$36,Supuestos!$D$35,IF(H5<=Supuestos!$C$38,Supuestos!$D$37,Supuestos!$D$39)) -> 85000 | I30: =IF(I5<=Supuestos!$C$36,Supuestos!$D$35,IF(I5<=Supuestos!$C$38,Supuestos!$D$37,Supuestos!$D$39)) -> 85000 | J30: =IF(J5<=Supuestos!$C$36,Supuestos!$D$35,IF(J5<=Supuestos!$C$38,Supuestos!$D$37,Supuestos!$D$39)) -> 85000 | ... BJ30: =IF(BJ5<=Supuestos!$C$36,Supuestos!$D$35,IF(BJ5<=Supuestos!$C$38,Supuestos!$D$37,Supuestos!$D$39)) -> 85000
B31: Pago total a PagaTodo (incl. su % del MDR y setup) | C31: =MAX(C29,C30)+C22 -> 136066.8 | D31: =MAX(D29,D30)+D22 -> 21416.99 | E31: =MAX(E29,E30)+E22 -> 42833.98 | F31: =MAX(F29,F30)+F22 -> 68534.368 | G31: =MAX(G29,G30)+G22 -> 226018.15 | H31: =MAX(H29,H30)+H22 -> 132785.34 | I31: =MAX(I29,I30)+I22 -> 175789.32 | J31: =MAX(J29,J30)+J22 -> 223161.7 | ... BJ31: =MAX(BJ29,BJ30)+BJ22 -> 3218468.1
B32: Auxiliar: mes si utilidad acumulada ≥ 0 | C32: =IF(C26>=0,C5,999) -> 1 | D32: =IF(D26>=0,D5,999) -> 2 | E32: =IF(E26>=0,E5,999) -> 3 | F32: =IF(F26>=0,F5,999) -> 4 | G32: =IF(G26>=0,G5,999) -> 5 | H32: =IF(H26>=0,H5,999) -> 6 | I32: =IF(I26>=0,I5,999) -> 7 | J32: =IF(J26>=0,J5,999) -> 8 | ... BJ32: =IF(BJ26>=0,BJ5,999) -> 60

Sheet BP Efevoo
B2: Business Plan 60 meses | Sofo Plus como agregador marca blanca con Efevoo Pay (propuesta 25-sep-2026)
B3: Cifras en MXN. Sofo Plus retiene el margen MDR y paga a Efevoo cuotas fijas, por transacción, marcas, setup y terminales.
B5: Mes # | C5: ='Cartera 60M'!C62 -> 1 | D5: ='Cartera 60M'!D62 -> 2 | E5: ='Cartera 60M'!E62 -> 3 | F5: ='Cartera 60M'!F62 -> 4 | G5: ='Cartera 60M'!G62 -> 5 | H5: ='Cartera 60M'!H62 -> 6 | I5: ='Cartera 60M'!I62 -> 7 | J5: ='Cartera 60M'!J62 -> 8 | ... BJ5: ='Cartera 60M'!BJ62 -> 60
B6: Año | C6: ='Cartera 60M'!C63 -> 1 | D6: ='Cartera 60M'!D63 -> 1 | E6: ='Cartera 60M'!E63 -> 1 | F6: ='Cartera 60M'!F63 -> 1 | G6: ='Cartera 60M'!G63 -> 1 | H6: ='Cartera 60M'!H63 -> 1 | I6: ='Cartera 60M'!I63 -> 1 | J6: ='Cartera 60M'!J63 -> 1 | ... BJ6: ='Cartera 60M'!BJ63 -> 5
B7: Créditos vigentes | C7: ='Cartera 60M'!C66 -> 2 | D7: ='Cartera 60M'!D66 -> 5 | E7: ='Cartera 60M'!E66 -> 10 | F7: ='Cartera 60M'!F66 -> 16 | G7: ='Cartera 60M'!G66 -> 23 | H7: ='Cartera 60M'!H66 -> 31 | I7: ='Cartera 60M'!I66 -> 41 | J7: ='Cartera 60M'!J66 -> 52 | ... BJ7: ='Cartera 60M'!BJ66 -> 744
B8: TPV activas | C8: ='Cartera 60M'!C67 -> 2 | D8: ='Cartera 60M'!D67 -> 5 | E8: ='Cartera 60M'!E67 -> 10 | F8: ='Cartera 60M'!F67 -> 16 | G8: ='Cartera 60M'!G67 -> 23 | H8: ='Cartera 60M'!H67 -> 31 | I8: ='Cartera 60M'!I67 -> 41 | J8: ='Cartera 60M'!J67 -> 52 | ... BJ8: ='Cartera 60M'!BJ67 -> 744
B9: Cartera al cierre (MXN) | C9: ='Cartera 60M'!C75 -> 2785593.9 | D9: ='Cartera 60M'!D75 -> 6743682.4 | E9: ='Cartera 60M'!E75 -> 13150853 | F9: ='Cartera 60M'!F75 -> 20384752 | G9: ='Cartera 60M'!G75 -> 28319663 | H9: ='Cartera 60M'!H75 -> 36826408 | I9: ='Cartera 60M'!I75 -> 47165059 | J9: ='Cartera 60M'!J75 -> 57696289 | ... BJ9: ='Cartera 60M'!BJ75 -> 5.4151201e+08
B11: Ingresos Sofo Plus
B12: Comisión de apertura | C12: ='Cartera 60M'!C70*Supuestos!$C$17 -> 90000 | D12: ='Cartera 60M'!D70*Supuestos!$C$17 -> 135000 | E12: ='Cartera 60M'!E70*Supuestos!$C$17 -> 225000 | F12: ='Cartera 60M'!F70*Supuestos!$C$17 -> 270000 | G12: ='Cartera 60M'!G70*Supuestos!$C$17 -> 315000 | H12: ='Cartera 60M'!H70*Supuestos!$C$17 -> 360000 | I12: ='Cartera 60M'!I70*Supuestos!$C$17 -> 450000 | J12: ='Cartera 60M'!J70*Supuestos!$C$17 -> 495000 | ... BJ12: ='Cartera 60M'!BJ70*Supuestos!$C$17 -> 2790000
B13: Intereses | C13: ='Cartera 60M'!C72 -> 82500 | D13: ='Cartera 60M'!D72 -> 200353.83 | E13: ='Cartera 60M'!E72 -> 391701.27 | F13: ='Cartera 60M'!F72 -> 609148.46 | G13: ='Cartera 60M'!G72 -> 849330.69 | H13: ='Cartera 60M'!H72 -> 1108790.7 | I13: ='Cartera 60M'!I72 -> 1425226.2 | J13: ='Cartera 60M'!J72 -> 1750789.1 | ... BJ13: ='Cartera 60M'!BJ72 -> 17449080
B14: MDR — margen neto retenido por Sofo Plus | C14: ='Cartera 60M'!C76*Supuestos!$C$57 -> 12000 | D14: ='Cartera 60M'!D76*Supuestos!$C$57 -> 30000 | E14: ='Cartera 60M'!E76*Supuestos!$C$57 -> 60000 | F14: ='Cartera 60M'!F76*Supuestos!$C$57 -> 96000 | G14: ='Cartera 60M'!G76*Supuestos!$C$57 -> 138000 | H14: ='Cartera 60M'!H76*Supuestos!$C$57 -> 186000 | I14: ='Cartera 60M'!I76*Supuestos!$C$57 -> 246000 | J14: ='Cartera 60M'!J76*Supuestos!$C$57 -> 312000 | ... BJ14: ='Cartera 60M'!BJ76*Supuestos!$C$57 -> 4464000
B15: Total ingresos | C15: =SUM(C12:C14) -> 184500 | D15: =SUM(D12:D14) -> 365353.83 | E15: =SUM(E12:E14) -> 676701.27 | F15: =SUM(F12:F14) -> 975148.46 | G15: =SUM(G12:G14) -> 1302330.7 | H15: =SUM(H12:H14) -> 1654790.7 | I15: =SUM(I12:I14) -> 2121226.2 | J15: =SUM(J12:J14) -> 2557789.1 | ... BJ15: =SUM(BJ12:BJ14) -> 24703080
B17: Costos Sofo Plus
B18: Costo de fondeo | C18: ='Cartera 60M'!C71*Supuestos!$C$16/12 -> 28950 | D18: ='Cartera 60M'!D71*Supuestos!$C$16/12 -> 70305.981 | E18: ='Cartera 60M'!E71*Supuestos!$C$16/12 -> 137451.53 | F18: ='Cartera 60M'!F71*Supuestos!$C$16/12 -> 213755.73 | G18: ='Cartera 60M'!G71*Supuestos!$C$16/12 -> 298037.86 | H18: ='Cartera 60M'!H71*Supuestos!$C$16/12 -> 389084.74 | I18: ='Cartera 60M'!I71*Supuestos!$C$16/12 -> 500124.84 | J18: ='Cartera 60M'!J71*Supuestos!$C$16/12 -> 614367.82 | ... BJ18: ='Cartera 60M'!BJ71*Supuestos!$C$16/12 -> 6123040.9
B19: Cuota fija Efevoo (dashboard + switch + servidores) | C19: =Supuestos!$D$50 -> 67150 | D19: =Supuestos!$D$50 -> 67150 | E19: =Supuestos!$D$50 -> 67150 | F19: =Supuestos!$D$50 -> 67150 | G19: =Supuestos!$D$50 -> 67150 | H19: =Supuestos!$D$50 -> 67150 | I19: =Supuestos!$D$50 -> 67150 | J19: =Supuestos!$D$50 -> 67150 | ... BJ19: =Supuestos!$D$50 -> 67150
B20: Costo por transacción Efevoo | C20: =MAX('Cartera 60M'!C77*Supuestos!$C$51,Supuestos!$C$52)*Supuestos!$C$7 -> 2040 | D20: =MAX('Cartera 60M'!D77*Supuestos!$C$51,Supuestos!$C$52)*Supuestos!$C$7 -> 5100 | E20: =MAX('Cartera 60M'!E77*Supuestos!$C$51,Supuestos!$C$52)*Supuestos!$C$7 -> 10200 | F20: =MAX('Cartera 60M'!F77*Supuestos!$C$51,Supuestos!$C$52)*Supuestos!$C$7 -> 16320 | G20: =MAX('Cartera 60M'!G77*Supuestos!$C$51,Supuestos!$C$52)*Supuestos!$C$7 -> 23460 | H20: =MAX('Cartera 60M'!H77*Supuestos!$C$51,Supuestos!$C$52)*Supuestos!$C$7 -> 31620 | I20: =MAX('Cartera 60M'!I77*Supuestos!$C$51,Supuestos!$C$52)*Supuestos!$C$7 -> 41820 | J20: =MAX('Cartera 60M'!J77*Supuestos!$C$51,Supuestos!$C$52)*Supuestos!$C$7 -> 53040 | ... BJ20: =MAX('Cartera 60M'!BJ77*Supuestos!$C$51,Supuestos!$C$52)*Supuestos!$C$7 -> 758880
B21: Registro anual ante marcas (Visa/MC) | C21: =IF(AND(C5>=Supuestos!$C$54,MOD(C5-Supuestos!$C$54,12)=0),Supuestos!$D$53,0) -> 0 | D21: =IF(AND(D5>=Supuestos!$C$54,MOD(D5-Supuestos!$C$54,12)=0),Supuestos!$D$53,0) -> 0 | E21: =IF(AND(E5>=Supuestos!$C$54,MOD(E5-Supuestos!$C$54,12)=0),Supuestos!$D$53,0) -> 0 | F21: =IF(AND(F5>=Supuestos!$C$54,MOD(F5-Supuestos!$C$54,12)=0),Supuestos!$D$53,0) -> 0 | G21: =IF(AND(G5>=Supuestos!$C$54,MOD(G5-Supuestos!$C$54,12)=0),Supuestos!$D$53,0) -> 0 | H21: =IF(AND(H5>=Supuestos!$C$54,MOD(H5-Supuestos!$C$54,12)=0),Supuestos!$D$53,0) -> 0 | I21: =IF(AND(I5>=Supuestos!$C$54,MOD(I5-Supuestos!$C$54,12)=0),Supuestos!$D$53,0) -> 0 | J21: =IF(AND(J5>=Supuestos!$C$54,MOD(J5-Supuestos!$C$54,12)=0),Supuestos!$D$53,0) -> 0 | ... BJ21: =IF(AND(BJ5>=Supuestos!$C$54,MOD(BJ5-Supuestos!$C$54,12)=0),Supuestos!$D$53,0) -> 0
B22: Implementación (setup) | C22: =IF(C5=1,Supuestos!$D$46,0) -> 340000 | D22: =IF(D5=1,Supuestos!$D$46,0) -> 0 | E22: =IF(E5=1,Supuestos!$D$46,0) -> 0 | F22: =IF(F5=1,Supuestos!$D$46,0) -> 0 | G22: =IF(G5=1,Supuestos!$D$46,0) -> 0 | H22: =IF(H5=1,Supuestos!$D$46,0) -> 0 | I22: =IF(I5=1,Supuestos!$D$46,0) -> 0 | J22: =IF(J5=1,Supuestos!$D$46,0) -> 0 | ... BJ22: =IF(BJ5=1,Supuestos!$D$46,0) -> 0
B23: Compra de TPV | C23: ='Cartera 60M'!C79*Supuestos!$D$55 -> 4454 | D23: ='Cartera 60M'!D79*Supuestos!$D$55 -> 6681 | E23: ='Cartera 60M'!E79*Supuestos!$D$55 -> 11135 | F23: ='Cartera 60M'!F79*Supuestos!$D$55 -> 13362 | G23: ='Cartera 60M'!G79*Supuestos!$D$55 -> 15589 | H23: ='Cartera 60M'!H79*Supuestos!$D$55 -> 17816 | I23: ='Cartera 60M'!I79*Supuestos!$D$55 -> 22270 | J23: ='Cartera 60M'!J79*Supuestos!$D$55 -> 24497 | ... BJ23: ='Cartera 60M'!BJ79*Supuestos!$D$55 -> 0
B24: Costo operativo propio como agregador | C24: =Supuestos!$C$58 -> 0 | D24: =Supuestos!$C$58 -> 0 | E24: =Supuestos!$C$58 -> 0 | F24: =Supuestos!$C$58 -> 0 | G24: =Supuestos!$C$58 -> 0 | H24: =Supuestos!$C$58 -> 0 | I24: =Supuestos!$C$58 -> 0 | J24: =Supuestos!$C$58 -> 0 | ... BJ24: =Supuestos!$C$58 -> 0
B25: Total costos | C25: =SUM(C18:C24) -> 442594 | D25: =SUM(D18:D24) -> 149236.98 | E25: =SUM(E18:E24) -> 225936.53 | F25: =SUM(F18:F24) -> 310587.73 | G25: =SUM(G18:G24) -> 404236.86 | H25: =SUM(H18:H24) -> 505670.74 | I25: =SUM(I18:I24) -> 631364.84 | J25: =SUM(J18:J24) -> 759054.82 | ... BJ25: =SUM(BJ18:BJ24) -> 6949070.9
B27: Utilidad mensual Sofo Plus | C27: =C15-C25 -> -258094 | D27: =D15-D25 -> 216116.85 | E27: =E15-E25 -> 450764.73 | F27: =F15-F25 -> 664560.73 | G27: =G15-G25 -> 898093.83 | H27: =H15-H25 -> 1149120 | I27: =I15-I25 -> 1489861.4 | J27: =J15-J25 -> 1798734.3 | ... BJ27: =BJ15-BJ25 -> 17754009
B28: Utilidad acumulada | C28: =C27 -> -258094 | D28: =C28+D27 -> -41977.149 | E28: =D28+E27 -> 408787.58 | F28: =E28+F27 -> 1073348.3 | G28: =F28+G27 -> 1971442.1 | H28: =G28+H27 -> 3120562.1 | I28: =H28+I27 -> 4610423.5 | J28: =I28+J27 -> 6409157.8 | K28: =J28+K27 -> 8525182.6 | ... BJ28: =BI28+BJ27 -> 5.8287508e+08
B29: Margen sobre ingresos | C29: =IF(C15=0,0,C27/C15) -> -1.3988835 | D29: =IF(D15=0,0,D27/D15) -> 0.59152753 | E29: =IF(E15=0,0,E27/E15) -> 0.66612071 | F29: =IF(F15=0,0,F27/F15) -> 0.68149698 | G29: =IF(G15=0,0,G27/G15) -> 0.68960506 | H29: =IF(H15=0,0,H27/H15) -> 0.69442012 | I29: =IF(I15=0,0,I27/I15) -> 0.70235855 | J29: =IF(J15=0,0,J27/J15) -> 0.70323792 | ... BJ29: =IF(BJ15=0,0,BJ27/BJ15) -> 0.71869618
B30: Pagos a Efevoo
B31: Pago total a Efevoo (fijos + transacciones + marcas + setup + TPV) | C31: =SUM(C19:C23) -> 413644 | D31: =SUM(D19:D23) -> 78931 | E31: =SUM(E19:E23) -> 88485 | F31: =SUM(F19:F23) -> 96832 | G31: =SUM(G19:G23) -> 106199 | H31: =SUM(H19:H23) -> 116586 | I31: =SUM(I19:I23) -> 131240 | J31: =SUM(J19:J23) -> 144687 | ... BJ31: =SUM(BJ19:BJ23) -> 826030
B32: Auxiliar: mes si utilidad acumulada ≥ 0 | C32: =IF(C28>=0,C5,999) -> 999 | D32: =IF(D28>=0,D5,999) -> 999 | E32: =IF(E28>=0,E5,999) -> 3 | F32: =IF(F28>=0,F5,999) -> 4 | G32: =IF(G28>=0,G5,999) -> 5 | H32: =IF(H28>=0,H5,999) -> 6 | I32: =IF(I28>=0,I5,999) -> 7 | J32: =IF(J28>=0,J5,999) -> 8 | ... BJ32: =IF(BJ28>=0,BJ5,999) -> 60

Sheet Economía por Crédito
B2: Economía en régimen por crédito vigente | PagaTodo vs Efevoo (MXN / mes)
B3: Promedio durante la vida del crédito. Sirve para ver el punto de equilibrio y a partir de cuántos créditos conviene cada proveedor.
B5: Concepto | C5: PagaTodo | D5: Efevoo
B6: Saldo insoluto promedio por crédito | C6: =Supuestos!$C$13*'Cartera 60M'!$C$12/Supuestos!$C$15 -> 727838.72 | D6: =Supuestos!$C$13*'Cartera 60M'!$C$12/Supuestos!$C$15 -> 727838.72
B7: Intereses | C7: =C6*Supuestos!$C$14/12 -> 20015.565 | D7: =D6*Supuestos!$C$14/12 -> 20015.565
B8: MDR que retiene Sofo Plus | C8: =Supuestos!$C$11*Supuestos!$C$20*(1-Supuestos!$C$33)*Supuestos!$C$18 -> 3000 | D8: =Supuestos!$C$11*Supuestos!$C$57*Supuestos!$C$18 -> 6000
B9: Comisión de apertura (amortizada en el plazo) | C9: =Supuestos!$C$13*Supuestos!$C$17/Supuestos!$C$15 -> 3750 | D9: =Supuestos!$C$13*Supuestos!$C$17/Supuestos!$C$15 -> 3750
B10: Total ingresos por crédito vigente | C10: =SUM(C7:C9) -> 26765.565 | D10: =SUM(D7:D9) -> 29765.565
B12: Costo de fondeo | C12: =C6*Supuestos!$C$16/12 -> 7023.6436 | D12: =D6*Supuestos!$C$16/12 -> 7023.6436
B13: Servicing fee PagaTodo (sobre cuota cobrada) | C13: ='Cartera 60M'!$C$8*Supuestos!$C$34 -> 1113.398 | D13: 0
B14: Renta TPV PagaTodo (mes 7+) / costo por transacción Efevoo | C14: =Supuestos!$D$31*Supuestos!$C$18 -> 255 | D14: =IF(Supuestos!$C$19=0,0,Supuestos!$C$11/Supuestos!$C$19)*Supuestos!$D$51*Supuestos!$C$18 -> 1020
B15: Compra de TPV amortizada en el plazo (solo si no se reutilizan) | C15: 0 | D15: =IF(Supuestos!$C$56=1,0,Supuestos!$D$55*Supuestos!$C$18/Supuestos!$C$15) -> 0
B16: Total costos variables por crédito vigente | C16: =SUM(C12:C15) -> 8392.0416 | D16: =SUM(D12:D15) -> 8043.6436
B17: Contribución neta por crédito vigente | C17: =C10-C16 -> 18373.523 | D17: =D10-D16 -> 21721.921
B19: Costo fijo mensual en régimen (PagaTodo: mínimo; Efevoo: cuota fija + marcas/12 + operación propia) | C19: =Supuestos!$D$39 -> 85000 | D19: =Supuestos!$D$50+Supuestos!$D$53/12+Supuestos!$C$58 -> 81316.667
B20: Margen que genera cada crédito para PagaTodo (cuenta contra el mínimo) | C20: =Supuestos!$C$11*Supuestos!$C$20*Supuestos!$C$33*Supuestos!$C$18+C13+C14 -> 4368.398 | D20: 0
B22: Créditos vigentes para utilidad mensual = 0 (break-even) | C22: =IF(C17<=0,"no se alcanza",ROUNDUP(C19/(C17+C20),0)) -> 4 | D22: =IF(D17<=0,"no se alcanza",ROUNDUP(D19/D17,0)) -> 4
B24: Créditos vigentes a partir de los cuales conviene Efevoo (en régimen) | C24: =IF(D17<=C17,"nunca",IF(C20<=0,ROUNDUP(MAX(0,D19-C19)/(D17-C17),0),IF((C19/C20)*(D17-C17)-D19<0,ROUNDUP(D19/(D17-C17),0),IF(C19-D19>=0,0,ROUNDUP((D19-C19)/(D17-C17-C20),0))))) -> 25 | D24: Punto de cruce: por encima de este número de créditos vigentes, Efevoo deja más utilidad mensual.
B26: Utilidad mensual en régimen según créditos vigentes (MXN)
B27: Créditos vigentes | C27: PagaTodo | D27: Efevoo | E27: Diferencia (Efevoo − PagaTodo) | F27: Conviene
B28: 5 | C28: =B28*$C$17-MAX(0,$C$19-B28*$C$20) -> 28709.606 | D28: =B28*$D$17-$D$19 -> 27292.939 | E28: =D28-C28 -> -1416.6667 | F28: =IF(E28>0,"Efevoo","PagaTodo") -> PagaTodo
B29: 10 | C29: =B29*$C$17-MAX(0,$C$19-B29*$C$20) -> 142419.21 | D29: =B29*$D$17-$D$19 -> 135902.54 | E29: =D29-C29 -> -6516.6667 | F29: =IF(E29>0,"Efevoo","PagaTodo") -> PagaTodo
B30: 20 | C30: =B30*$C$17-MAX(0,$C$19-B30*$C$20) -> 367470.46 | D30: =B30*$D$17-$D$19 -> 353121.76 | E30: =D30-C30 -> -14348.707 | F30: =IF(E30>0,"Efevoo","PagaTodo") -> PagaTodo
B31: 30 | C31: =B31*$C$17-MAX(0,$C$19-B31*$C$20) -> 551205.69 | D31: =B31*$D$17-$D$19 -> 570340.97 | E31: =D31-C31 -> 19135.273 | F31: =IF(E31>0,"Efevoo","PagaTodo") -> Efevoo
B32: 50 | C32: =B32*$C$17-MAX(0,$C$19-B32*$C$20) -> 918676.16 | D32: =B32*$D$17-$D$19 -> 1004779.4 | E32: =D32-C32 -> 86103.233 | F32: =IF(E32>0,"Efevoo","PagaTodo") -> Efevoo
B33: 75 | C33: =B33*$C$17-MAX(0,$C$19-B33*$C$20) -> 1378014.2 | D33: =B33*$D$17-$D$19 -> 1547827.4 | E33: =D33-C33 -> 169813.18 | F33: =IF(E33>0,"Efevoo","PagaTodo") -> Efevoo
B34: 100 | C34: =B34*$C$17-MAX(0,$C$19-B34*$C$20) -> 1837352.3 | D34: =B34*$D$17-$D$19 -> 2090875.4 | E34: =D34-C34 -> 253523.13 | F34: =IF(E34>0,"Efevoo","PagaTodo") -> Efevoo
B35: 150 | C35: =B35*$C$17-MAX(0,$C$19-B35*$C$20) -> 2756028.5 | D35: =B35*$D$17-$D$19 -> 3176971.5 | E35: =D35-C35 -> 420943.03 | F35: =IF(E35>0,"Efevoo","PagaTodo") -> Efevoo
B36: 200 | C36: =B36*$C$17-MAX(0,$C$19-B36*$C$20) -> 3674704.6 | D36: =B36*$D$17-$D$19 -> 4263067.6 | E36: =D36-C36 -> 588362.93 | F36: =IF(E36>0,"Efevoo","PagaTodo") -> Efevoo
B37: 300 | C37: =B37*$C$17-MAX(0,$C$19-B37*$C$20) -> 5512056.9 | D37: =B37*$D$17-$D$19 -> 6435259.7 | E37: =D37-C37 -> 923202.73 | F37: =IF(E37>0,"Efevoo","PagaTodo") -> Efevoo
B38: 500 | C38: =B38*$C$17-MAX(0,$C$19-B38*$C$20) -> 9186761.6 | D38: =B38*$D$17-$D$19 -> 10779644 | E38: =D38-C38 -> 1592882.3 | F38: =IF(E38>0,"Efevoo","PagaTodo") -> Efevoo
B39: 750 | C39: =B39*$C$17-MAX(0,$C$19-B39*$C$20) -> 13780142 | D39: =B39*$D$17-$D$19 -> 16210124 | E39: =D39-C39 -> 2429981.8 | F39: =IF(E39>0,"Efevoo","PagaTodo") -> Efevoo
B40: 1000 | C40: =B40*$C$17-MAX(0,$C$19-B40*$C$20) -> 18373523 | D40: =B40*$D$17-$D$19 -> 21640604 | E40: =D40-C40 -> 3267081.3 | F40: =IF(E40>0,"Efevoo","PagaTodo") -> Efevoo
B42: Nota: en régimen se usa la renta de TPV del mes 7+ y el mínimo de PagaTodo del mes 5+. No incluye setup ni el arranque; esos sí están en los Business Plan de 60 meses.
